Workbook

Sheet Index
B2: FINANCIAL MANAGEMENT ECON F315 FIN F315
B4: Group Number | C4: 11
B5: Company Name | C5: Tech Mahindra | F5: INDEX
B7: Group Members | E7: Sheet Number | F7: Sheet Name | G7: Description
B8: Name | C8: ID | E8: 1 | F8: Front page | G8: Contributions
B9: AMAN TOMY | C9: 2023A4PS1174G | E9: 2 | F9: Cost of equity | G9: Finding the cost of equity using CAPM & DDM , Justifying why CAPM is better in our companies case
B10: GRACE PAUL | C10: 2023A4PS0277G | E10: 3 | F10: Cost of debt | G10: Finding Cost of Debt using Total Interest expenses/Total Borrowings (1-tax rate)
B11: JATIN SINGH | C11: 2023A4PS0286G | E11: 4 | F11: PART-A answer | G11: Final WACC calculations using equity and debt weights
B12: LIKHIT SRIVASTAVA | C12: 2023A4PS0259G | E12: 5 | F12: PART-B answer | G12: Computing the theoretical ex-rights, value of one right and percentage price drop
B13: NEEL NIRAJ UDAIPURIA | C13: 2023A4PS0269G | E13: 6 | F13: PART-C answer | G13: Computing PV/NPV of leasing vs Ownership to determine which is cheaper and optimal , Sensitivity analysis
B14: PREM CHANDRESH | C14: 2023A4PS0279G
B15: S ANANTHA KRISHNAN | C15: 2023A1PS1207G
B16: SATYA PRAKASH PURRE | C16: 2023A1PS1193G
B17: VAISHNAVI YUVARAJ POTEKAR | C17: 2023A7PS0488G
B18: VEDANT GIRISH PATIL | C18: 2023A4PS0305G
B21: Contributions | E21: (Note) :
B22: AMAN TOMY | C22: 0.1 | E22: Everyone contributed their equal share and also re-verified everyone elses values to correct any mistakes
B23: GRACE PAUL | C23: 0.1 | E23: Everyone is thorough with the entire procedure of the assignment
B24: JATIN SINGH | C24: 0.1
B25: LIKHIT SRIVASTAVA | C25: 0.1
B26: NEEL NIRAJ UDAIPURIA | C26: 0.1
B27: PREM CHANDRESH | C27: 0.1
B28: S ANANTHA KRISHNAN | C28: 0.1
B29: SATYA PRAKASH PURRE | C29: 0.1
B30: VAISHNAVI YUVARAJ POTEKAR | C30: 0.1
B31: VEDANT GIRISH PATIL | C31: 0.1

Sheet Financial Statements
B3: INCOME STATEMENT
B5: Particulars | C5: FY 2024-25 | D5: FY 2023-24 | E5: FY 2022-23 | F5: FY 2021-22 | G5: FY 2020-21
B6: Revenue from Operations | C6: 529883 | D6: 519955 | E6: 532902 | F6: 446460 | G6: 378551
B7: Other Income | C7: 8554 | D7: 9169 | E7: 9650 | F7: 11420 | G7: 7871
B8: Total Income | C8: 538437 | D8: 529124 | E8: 542552 | F8: 457880 | G8: 386422
B9: Expenses
B10: Employee Benefits Expense | C10: 296238 | D10: 291283 | E10: 276918 | F10: 222859 | G10: 192973
B11: Subcontracting Expenses | C11: 58377 | D11: 66889 | E11: 80002 | F11: 69571 | G11: 49743
B12: Finance Costs | C12: 3217 | D12: 3922 | E12: 3256 | F12: 1626 | G12: 1740
B13: Depreciation & Amortisation | C13: 18529 | D13: 18171 | E13: 19567 | F13: 15204 | G13: 14577
B14: Other Expenses | C14: 105357 | D14: 112138 | E14: 95694 | F14: 73830 | G14: 67365
B15: Impairment of Goodwill/Assets | C15: 273 | D15: 4582 | E15: 2370 | F15: - | G15: 507
B16: Total Expenses | C16: 481991 | D16: 496985 | E16: 477807 | F16: 383090 | G16: 326905
B17: Share in Profit/(Loss) of Associates | C17: 86 | D17: 105 | E17: -290 | F17: 28 | G17: 12
B18: Profit Before Tax (PBT) | C18: 56532 | D18: 32244 | E18: 64455 | F18: 74493 | G18: 59517
B19: Tax Expense | C19: 14002 | D19: 8276 | E19: 15885 | F19: 18220 | G19: 15999
B20: Profit After Tax (PAT) | C20: 42530 | D20: 23968 | E20: 48570 | F20: 56273 | G20: 43518
B21: Diluted EPS (INR) | C21: 47.91 | D21: 26.58 | E21: 54.54 | F21: 62.81 | G21: 50.19
B24: BALANCE SHEET
B26: Particulars | C26: FY 2024-25 | D26: FY 2023-24 | E26: FY 2022-23 | F26: FY 2021-22 | G26: FY 2020-21
B27: ASSETS
B28: Non-Current Assets
B29: Property, Plant & Equipment | C29: 23805 | D29: 25577 | E29: 28622 | F29: 26823 | G29: 24632
B30: Right-of-Use Asset | C30: 15186 | D30: 9605 | E30: 10972 | F30: 9372 | G30: 10072
B31: Goodwill | C31: 76993 | D31: 75106 | E31: 76657 | F31: 74258 | G31: 40082
B32: Other Intangible Assets | C32: 23491 | D32: 28029 | E32: 32316 | F32: 36586 | G32: 14508
B33: Investments | C33: 2354 | D33: 4122 | E33: 4320 | F33: 2510 | G33: 5478
B34: Other Fin. & Non-Current Assets | C34: 66306 | D34: 63930 | E34: 64319 | F34: 54601 | G34: 49455
B35: Total Non-Current Assets | C35: 208135 | D35: 206369 | E35: 217206 | F35: 204150 | G35: 144227
B36: Current Assets
B37: Investments | C37: 32110 | D37: 27794 | E37: 27832 | F37: 44359 | G37: 96619
B38: Trade Receivables | C38: 131065 | D38: 114011 | E38: 128816 | F38: 119334 | G38: 64728
B39: Cash & Cash Equivalents | C39: 35150 | D39: 43471 | E39: 40563 | F39: 37889 | G39: 26904
B40: Other Current Assets | C40: 38485 | D40: 42591 | E40: 47116 | F40: 42975 | G40: 64302
B41: Total Current Assets | C41: 236810 | D41: 227867 | E41: 244327 | F41: 244557 | G41: 252553
B42: TOTAL ASSETS | C42: 444945 | D42: 434236 | E42: 461533 | F42: 448707 | G42: 396780
B44: EQUITY AND LIABILITIES
B45: Equity
B46: Equity Share Capital | C46: 4424 | D46: 4423 | E46: 4400 | F46: 4388 | G46: 4370
B47: Other Equity (Reserves) | C47: 269191 | D47: 262281 | E47: 274845 | F47: 264469 | G47: 244280
...

Sheet Cost of Equity
A2: CAPM MODEL | I2: DDM MODEL
A3: F.Y | B3: 2020-21 | C3: 2021-22 | D3: 2022-23 | E3: 2023-24 | F3: 2024-25 | I3: F.Y | J3: 2020-21 | K3: 2021-22 | L3: 2022-23 | M3: 2023-24 | N3: 2024-25
A4: Rm (Market Return during that year) | B4: =S45/S292-1 -> 0.79725419 | C4: =Y45/Y291-1 -> 0.18831055 | D4: =AE45/AE293-1 -> -0.0058188537 | E4: =AK45/AK287-1 -> 0.27423134 | F4: =AQ45/AQ291-1 -> 0.060120431 | I4: Interim Dividends | J4: - | K4: - | L4: - | M4: 12 | N4: 15
A5: RFR (risk free rate) | B5: =B41 -> 0.060062451 | C5: =C41 -> 0.063836475 | D5: =D41 -> 0.073322131 | E5: =E41 -> 0.071617814 | F5: =F41 -> 0.068863636 | I5: Final Dividends | J5: 15 | K5: 15 | L5: 32 | M5: 28 | N5: 30
A6: Risk Premium | B6: =B4-B5 -> 0.73719174 | C6: =C4-C5 -> 0.12447407 | D6: =D4-D5 -> -0.079140985 | E6: =E4-E5 -> 0.20261352 | F6: =F4-F5 -> -0.008743205 | I6: Special Dividends | J6: 30 | K6: 30 | L6: 18 | M6: - | N6: 15
A7: Beta | B7: =SLOPE(T45:T292,U45:U292) -> -0.0054268514 | C7: =SLOPE(Z45:Z291,AA45:AA291) -> 0.10687713 | D7: =SLOPE(AF45:AF293,AG45:AG293) -> 0.090141316 | E7: =SLOPE(AL45:AL287,AM45:AM287) -> 0.23618984 | F7: =SLOPE(AR45:AR289,AS45:AS289) -> 0.34649014 | I7: Total Dividends (D0) | J7: =SUM(J4:J6) -> 45 | K7: =SUM(K4:K6) -> 45 | L7: =SUM(L4:L6) -> 50 | M7: =SUM(M4:M6) -> 40 | N7: =SUM(N4:N6) -> 60
A8: Ke | B8: =B5+(B7*B6) -> 0.056061821 | C8: =C5+(C7*C6) -> 0.077139908 | D8: =D5+(D7*D6) -> 0.066188259 | E8: =E5+(E7*E6) -> 0.11947307 | F8: =F5+(F7*F6) -> 0.065834202 | I8: Closing Price (P0) | J8: 991.45 | K8: 1499.5 | L8: 1101.85 | M8: 1248.1 | N8: 1418.25
I9: Retention Ratio | J9: 0.5438 | K9: 0.112 | L9: -0.2363 | M9: -1.0155 | N9: -0.1997
A10: - The risk-free rate was calculated using the 10-year bond yield of India - Beta was estimated by regression. ( Regression of Stock returns vs Market Returns, slope of the line is Beta) ( ALL historical data series are attached below) | I10: Return on Equity | J10: 0.1694 | K10: 0.19 | L10: 0.1521 | M10: 0.0918 | N10: 0.1563
I11: Growth Rate (g) | J11: 0.09211972 | K11: 0.02128 | L11: -0.03594123 | M11: -0.0932229 | N11: -0.03121311
I12: Expected Dividend (D1) | J12: =J7*(1+J11) -> 49.145387 | K12: =K7*(1+K11) -> 45.9576 | L12: =L7*(1+L11) -> 48.202938 | M12: =M7*(1+M11) -> 36.271084 | N12: =N7*(1+N11) -> 58.127213
I13: Dividend Yield | J13: =J12/J8 -> 0.049569204 | K13: =K12/K8 -> 0.030648616 | L13: =L12/L8 -> 0.043747278 | M13: =M12/M8 -> 0.02906104 | N13: =N12/N8 -> 0.040985167
I14: Cost of Equity (Ke) | J14: =J13+J11 -> 0.14168892 | K14: =K13+K11 -> 0.051928616 | L14: =L13+L11 -> 0.0078060482 | M14: =M13+M11 -> -0.06416186 | N14: =N13+N11 -> 0.0097720572
A18: Sources | M18: Sources
A19: 10 Year Bond Yield Rate | M19: Tech Mahindra Closing Prices
A20: Tech Mahindra HIstorical prices | M20: Key Financial Ratios
A21: Adjusted default spread | M21: Dividends
A22: NIFTY 50 TRI prices
A23: Tech-M Annual Reports
C30: We calculated the cost of equity using both CAPM and the DDM. However, the DDM gave highly inconsistent results because the company’s dividends do not grow consistently. Therefore, the CAPM MODEL is more reliable in this case, since it is based on market-driven risk measures rather than unstable dividend patterns.
A40: India 10 year bond yield | B40: 2020-21 | C40: 2021-22 | D40: 2022-23 | E40: 2023-24 | F40: 2024-25
A41: RFR | B41: =AVERAGE(B47:B301) -> 0.060062451 | C41: =AVERAGE(E47:E292) -> 0.063836475 | D41: =AVERAGE(H47:H292) -> 0.073322131 | E41: =AVERAGE(K47:K295) -> 0.071617814 | F41: =AVERAGE(N47:N290) -> 0.068863636
Q42: LAST 5 YEARS DAILY RETURNS OF TECH MAHINDRA VS LAST 5 YEARS DAILY MARKET(NIFTY 50) RETURNS , REGRESSION TO OBTAIN BETA OF THE FIRM
A43: India 10 year bond yield | Q43: FY 2020-21 | W43: FY 2021-22 | AC43: FY 2022-23 | AI43: FY 2023-24 | AO43: FY 2024-25
A44: Date | B44: Close | D44: Date | E44: Close | G44: Date | H44: Close | J44: Date | K44: Close | M44: Date | N44: Close | Q44: Date | R44: Tech_M | S44: Price | T44: TECH_R | U44: NIFTY_R | W44: Date | X44: Close | Y44: Price | Z44: TECH_R | AA44: NIFTY_R | AC44: Date | AD44: Close | AE44: Price | AF44: TECH_R | AG44: NIFTY_R | AI44: Date | AJ44: Close | AK44: Price | AL44: TECH_R | AM44: NIFTY_R | AO44: Date | AP44: Close | AQ44: Price | AR44: TECH_R | AS44: NIFTY_R
A45: 44286 | B45: 0.0633 | D45: 44651 | E45: 0.0684 | G45: 45016 | H45: 0.0732 | J45: 45382 | K45: 0.0706 | M45: 45747 | N45: 0.0658 | Q45: 44286 | R45: 991.25 | S45: 20886.52 | T45: =R45/R46-1 -> -0.025031966 | U45: =S45/S46-1 -> -0.010401752 | W45: 44651 | X45: 1499.3 | Y45: 25118.14 | Z45: =X45/X46-1 -> 0.0021054039 | AA45: =Y45/Y46-1 -> -0.0019140669 | AC45: 45016 | AD45: 1101.85 | AE45: 25266.06 | AF45: =AD45/AD46-1 -> 0.019052023 | AG45: =AE45/AE46-1 -> 0.016336731 | AI45: 45379 | AJ45: 1250.4 | AK45: 32867.23 | AL45: =AJ45/AJ46-1 -> -0.0025924301 | AM45: =AK45/AK46-1 -> 0.0091875432 | AO45: 45744 | AP45: 1418 | AQ45: 35054.08 | AR45: =AP45/AP46-1 -> -0.0035837257 | AS45: =AQ45/AQ46-1 -> -0.0030782952
A46: 44285 | B46: 0.0632 | D46: 44650 | E46: 0.0679 | G46: 45014 | H46: 0.0732 | J46: 45379 | K46: 0.0705 | M46: 45746 | N46: 0.0658 | Q46: 44285 | R46: 1016.7 | S46: 21106.06 | T46: =R46/R47-1 -> 0.025674653 | U46: =S46/S47-1 -> 0.023284926 | W46: 44650 | X46: 1496.15 | Y46: 25166.31 | Z46: =X46/X47-1 -> -0.01685504 | AA46: =Y46/Y47-1 -> 0.0099825143 | AC46: 45014 | AD46: 1081.25 | AE46: 24859.93 | AF46: =AD46/AD47-1 -> 0.010277972 | AG46: =AE46/AE47-1 -> 0.007610194 | AI46: 45378 | AJ46: 1253.65 | AK46: 32568.01 | AL46: =AJ46/AJ47-1 -> -0.00011963631 | AM46: =AK46/AK47-1 -> 0.0054045727 | AO46: 45743 | AP46: 1423.1 | AQ46: 35162.32 | AR46: =AP46/AP47-1 -> 0.0052981068 | AS46: =AQ46/AQ47-1 -> 0.0044749893
A47: 44283 | B47: 0.0628 | D47: 44649 | E47: 0.0683 | G47: 45013 | H47: 0.0733 | J47: 45378 | K47: 0.0707 | M47: 45744 | N47: 0.0659 | Q47: 44281 | R47: 991.25 | S47: 20625.79 | T47: =R47/R48-1 -> 0.021328113 | U47: =S47/S48-1 -> 0.012735179 | W47: 44649 | X47: 1521.8 | Y47: 24917.57 | Z47: =X47/X48-1 -> -0.001541843 | AA47: =Y47/Y48-1 -> 0.0060108145 | AC47: 45013 | AD47: 1070.25 | AE47: 24672.17 | AF47: =AD47/AD48-1 -> -0.02898748 | AG47: =AE47/AE48-1 -> -0.0020039067 | AI47: 45377 | AJ47: 1253.8 | AK47: 32392.94 | AL47: =AJ47/AJ48-1 -> -0.0090104331 | AM47: =AK47/AK48-1 -> -0.0041652794 | AO47: 45742 | AP47: 1415.6 | AQ47: 35005.67 | AR47: =AP47/AP48-1 -> -0.02848123 | AS47: =AQ47/AQ48-1 -> -0.0076815684
A48: 44281 | B48: 0.0628 | D48: 44648 | E48: 0.0684 | G48: 45012 | H48: 0.0732 | J48: 45377 | K48: 0.0709 | M48: 45743 | N48: 0.0659 | Q48: 44280 | R48: 970.55 | S48: 20366.42 | T48: =R48/R49-1 -> -0.024376759 | U48: =S48/S49-1 -> -0.01536675 | W48: 44648 | X48: 1524.15 | Y48: 24768.69 | Z48: =X48/X49-1 -> -0.0051240209 | AA48: =Y48/Y49-1 -> 0.0040227893 | AC48: 45012 | AD48: 1102.2 | AE48: 24721.71 | AF48: =AD48/AD49-1 -> 0.00059007762 | AG48: =AE48/AE49-1 -> 0.0023995916 | AI48: 45373 | AJ48: 1265.2 | AK48: 32528.43 | AL48: =AJ48/AJ49-1 -> -0.013296939 | AM48: =AK48/AK49-1 -> 0.0038523497 | AO48: 45741 | AP48: 1457.1 | AQ48: 35276.65 | AR48: =AP48/AP49-1 -> -0.0010283834 | AS48: =AQ48/AQ49-1 -> 0.00043617261
A49: 44280 | B49: 0.063 | D49: 44645 | E49: 0.0681 | G49: 45009 | H49: 0.0732 | J49: 45375 | K49: 0.071 | M49: 45742 | N49: 0.0661 | Q49: 44279 | R49: 994.8 | S49: 20684.27 | T49: =R49/R50-1 -> -0.018789762 | U49: =S49/S50-1 -> -0.017911813 | W49: 44645 | X49: 1532 | Y49: 24669.45 | Z49: =X49/X50-1 -> -0.023488543 | AA49: =Y49/Y50-1 -> -0.004049294 | AC49: 45009 | AD49: 1101.55 | AE49: 24662.53 | AF49: =AD49/AD50-1 -> 0.0016367356 | AG49: =AE49/AE50-1 -> -0.0077193606 | AI49: 45372 | AJ49: 1282.25 | AK49: 32403.6 | AL49: =AJ49/AJ50-1 -> 0.014879892 | AM49: =AK49/AK50-1 -> 0.0079140457 | AO49: 45740 | AP49: 1458.6 | AQ49: 35261.27 | AR49: =AP49/AP50-1 -> 0.034431403 | AS49: =AQ49/AQ50-1 -> 0.013187921
A50: 44279 | B50: 0.0632 | D50: 44644 | E50: 0.0683 | G50: 45008 | H50: 0.0734 | J50: 45373 | K50: 0.0706 | M50: 45741 | N50: 0.0663 | Q50: 44278 | R50: 1013.85 | S50: 21061.52 | T50: =R50/R51-1 -> 0.0010861516 | U50: =S50/S51-1 -> 0.005435932 | W50: 44644 | X50: 1568.85 | Y50: 24769.75 | Z50: =X50/X51-1 -> 0.017511431 | AA50: =Y50/Y51-1 -> -0.001330095 | AC50: 45008 | AD50: 1099.75 | AE50: 24854.39 | AF50: =AD50/AD51-1 -> 0.00068243858 | AG50: =AE50/AE51-1 -> -0.0043727755 | AI50: 45371 | AJ50: 1263.45 | AK50: 32149.17 | AL50: =AJ50/AJ51-1 -> 0.0088633369 | AM50: =AK50/AK51-1 -> 0.0009923001 | AO50: 45737 | AP50: 1410.05 | AQ50: 34802.3 | AR50: =AP50/AP51-1 -> -0.0003190358 | AS50: =AQ50/AQ51-1 -> 0.0068892131
A51: 44278 | B51: 0.0631 | D51: 44643 | E51: 0.0685 | G51: 45007 | H51: 0.0736 | J51: 45372 | K51: 0.0707 | M51: 45740 | N51: 0.0663 | Q51: 44277 | R51: 1012.75 | S51: 20947.65 | T51: =R51/R52-1 -> 0.02375537 | U51: =S51/S52-1 -> -0.0004399512 | W51: 44643 | X51: 1541.85 | Y51: 24802.74 | Z51: =X51/X52-1 -> 0.0022100166 | AA51: =Y51/Y52-1 -> -0.0040316201 | AC51: 45007 | AD51: 1099 | AE51: 24963.55 | AF51: =AD51/AD52-1 -> 0.0029202409 | AG51: =AE51/AE52-1 -> 0.0025936816 | AI51: 45370 | AJ51: 1252.35 | AK51: 32117.3 | AL51: =AJ51/AJ52-1 -> -0.015486813 | AM51: =AK51/AK52-1 -> -0.010801404 | AO51: 45736 | AP51: 1410.5 | AQ51: 34564.18 | AR51: =AP51/AP52-1 -> 0.010133563 | AS51: =AQ51/AQ52-1 -> 0.012355037
A52: 44277 | B52: 0.0634 | D52: 44642 | E52: 0.0686 | G52: 45006 | H52: 0.0736 | J52: 45371 | K52: 0.0718 | M52: 45737 | N52: 0.0663 | Q52: 44274 | R52: 989.25 | S52: 20956.87 | T52: =R52/R53-1 -> -0.0069266677 | U52: =S52/S53-1 -> 0.012783958 | W52: 44642 | X52: 1538.45 | Y52: 24903.14 | Z52: =X52/X53-1 -> 0.038335639 | AA52: =Y52/Y53-1 -> 0.011561215 | AC52: 45006 | AD52: 1095.8 | AE52: 24898.97 | AF52: =AD52/AD53-1 -> -0.011858064 | AG52: =AE52/AE53-1 -> 0.0070117611 | AI52: 45369 | AJ52: 1272.05 | AK52: 32468 | AL52: =AJ52/AJ53-1 -> -0.0076452003 | AM52: =AK52/AK53-1 -> -0.004163326 | AO52: 45735 | AP52: 1396.35 | AQ52: 34142.35 | AR52: =AP52/AP53-1 -> -0.024316109 | AS52: =AQ52/AQ53-1 -> 0.0032112893
A53: 44274 | B53: 0.0636 | D53: 44641 | E53: 0.0683 | G53: 45005 | H53: 0.0733 | J53: 45370 | K53: 0.0709 | M53: 45736 | N53: 0.0668 | Q53: 44273 | R53: 996.15 | S53: 20692.34 | T53: =R53/R54-1 -> -0.023573809 | U53: =S53/S54-1 -> -0.011100326 | W53: 44641 | X53: 1481.65 | Y53: 24618.52 | Z53: =X53/X54-1 -> -0.0068704337 | AA53: =Y53/Y54-1 -> -0.0098040123 | AC53: 45005 | AD53: 1108.95 | AE53: 24725.6 | AF53: =AD53/AD54-1 -> -0.015491832 | AG53: =AE53/AE54-1 -> -0.0065292248 | AI53: 45366 | AJ53: 1281.85 | AK53: 32603.74 | AL53: =AJ53/AJ54-1 -> -0.0093129299 | AM53: =AK53/AK54-1 -> 0.0056547712 | AO53: 45734 | AP53: 1431.15 | AQ53: 34033.06 | AR53: =AP53/AP54-1 -> -0.0059042128 | AS53: =AQ53/AQ54-1 -> 0.014462315
A54: 44273 | B54: 0.0641 | D54: 44637 | E54: 0.0681 | G54: 45002 | H54: 0.0737 | J54: 45369 | K54: 0.0708 | M54: 45735 | N54: 0.0672 | Q54: 44272 | R54: 1020.2 | S54: 20924.61 | T54: =R54/R55-1 -> -0.0075875486 | U54: =S54/S55-1 -> -0.012685517 | W54: 44637 | X54: 1491.9 | Y54: 24862.27 | Z54: =X54/X55-1 -> 0.001611279 | AA54: =Y54/Y55-1 -> 0.018361186 | AC54: 45002 | AD54: 1126.4 | AE54: 24888.1 | AF54: =AD54/AD55-1 -> 0.0077387609 | AG54: =AE54/AE55-1 -> 0.0067382588 | AI54: 45365 | AJ54: 1293.9 | AK54: 32420.41 | AL54: =AJ54/AJ55-1 -> 0.013392857 | AM54: =AK54/AK55-1 -> -0.0055543474 | AO54: 45733 | AP54: 1439.65 | AQ54: 33547.88 | AR54: =AP54/AP55-1 -> 0 | AS54: =AQ54/AQ55-1 -> 0.0049805851
A55: 44272 | B55: 0.064 | D55: 44636 | E55: 0.0684 | G55: 45001 | H55: 0.0736 | J55: 45366 | K55: 0.0706 | M55: 45734 | N55: 0.0674 | Q55: 44271 | R55: 1028 | S55: 21193.46 | T55: =R55/R56-1 -> 0.001754044 | U55: =S55/S56-1 -> -0.0012784753 | W55: 44636 | X55: 1489.5 | Y55: 24414 | Z55: =X55/X56-1 -> 0.020869744 | AA55: =Y55/Y56-1 -> 0.018747559 | AC55: 45001 | AD55: 1117.75 | AE55: 24721.52 | AF55: =AD55/AD56-1 -> 0.0029161059 | AG55: =AE55/AE56-1 -> 0.00080642549 | AI55: 45364 | AJ55: 1276.8 | AK55: 32601.49 | AL55: =AJ55/AJ56-1 -> -0.011764706 | AM55: =AK55/AK56-1 -> 0.0067713085 | AO55: 45729 | AP55: 1439.65 | AQ55: 33381.62 | AR55: =AP55/AP56-1 -> 0.0009038134 | AS55: =AQ55/AQ56-1 -> -0.0032620831
A56: 44271 | B56: 0.0639 | D56: 44635 | E56: 0.0687 | G56: 45000 | H56: 0.0739 | J56: 45365 | K56: 0.0704 | M56: 45733 | N56: 0.0675 | Q56: 44270 | R56: 1026.2 | S56: 21220.59 | T56: =R56/R57-1 -> 0.022213368 | U56: =S56/S57-1 -> -0.0065866809 | W56: 44635 | X56: 1459.05 | Y56: 23964.72 | Z56: =X56/X57-1 -> -0.029241517 | AA56: =Y56/Y57-1 -> -0.012346127 | AC56: 45000 | AD56: 1114.5 | AE56: 24701.6 | AF56: =AD56/AD57-1 -> -0.00089645899 | AG56: =AE56/AE57-1 -> -0.0041729305 | AI56: 45363 | AJ56: 1292 | AK56: 32382.22 | AL56: =AJ56/AJ57-1 -> 0.0018221998 | AM56: =AK56/AK57-1 -> -0.015131507 | AO56: 45728 | AP56: 1438.35 | AQ56: 33490.87 | AR56: =AP56/AP57-1 -> -0.027583409 | AS56: =AQ56/AQ57-1 -> -0.001217058
... A287: 43938 | B287: 0.0638 | D287: 44293 | E287: 0.0623 | G287: 44658 | H287: 0.0692 | J287: 45029 | K287: 0.0722 | M287: 45385 | N287: 0.0711 | Q287: 43934 | R287: 527.15 | S287: 12663.31 | T287: =R287/R288-1 -> -0.033018435 | U287: =S287/S288-1 -> -0.012959125 | W287: 44295 | X287: 1052.65 | Y287: 21149.59 | Z287: =X287/X288-1 -> 0.02367986 | AA287: =Y287/Y288-1 -> 0.003809805 | AC287: 44662 | AD287: 1448.7 | AE287: 25422.81 | AF287: =AD287/AD288-1 -> -0.0007242628 | AG287: =AE287/AE288-1 -> -0.0061508631 | AI287: 45019 | AJ287: 1103.1 | AK287: 25793.77 | AL287: =AJ287/AJ288-1 -> 0.0011344557 | AM287: =AK287/AK288-1 -> 0.0055764495 | AO287: 45387 | AP287: 1263.25 | AQ287: 33142.19 | AR287: =AP287/AP288-1 -> -0.012043953 | AS287: =AQ287/AQ288-1 -> -4.2240445e-05
A288: 43937 | B288: 0.0644 | D288: 44292 | E288: 0.0626 | G288: 44657 | H288: 0.0692 | J288: 45028 | K288: 0.0722 | M288: 45384 | N288: 0.0709 | Q288: 43930 | R288: 545.15 | S288: 12829.57 | T288: =R288/R289-1 -> -0.025734966 | U288: =S288/S289-1 -> 0.041509143 | W288: 44294 | X288: 1028.3 | Y288: 21069.32 | Z288: =X288/X289-1 -> 0.025173222 | AA288: =Y288/Y289-1 -> 0.0092328385 | AC288: 44659 | AD288: 1449.75 | AE288: 25580.15 | AF288: =AD288/AD289-1 -> -0.013070561 | AG288: =AE288/AE289-1 -> 0.008208694 | AI288: 45016 | AJ288: 1101.85 | AK288: 25650.73 | AO288: 45386 | AP288: 1278.65 | AQ288: 33143.59 | AR288: =AP288/AP289-1 -> 0.018033439 | AS288: =AQ288/AQ289-1 -> 0.0035659978
A289: 43936 | B289: 0.0648 | D289: 44291 | E289: 0.0627 | G289: 44656 | H289: 0.069 | J289: 45027 | K289: 0.0723 | Q289: 43929 | R289: 559.55 | S289: 12318.25 | T289: =R289/R290-1 -> 0.023879231 | U289: =S289/S290-1 -> -0.0049412654 | W289: 44293 | X289: 1003.05 | Y289: 20876.57 | Z289: =X289/X290-1 -> 0.011649017 | AA289: =Y289/Y290-1 -> 0.0031213347 | AC289: 44658 | AD289: 1468.95 | AE289: 25371.88 | AF289: =AD289/AD290-1 -> 0.0064748201 | AG289: =AE289/AE290-1 -> -0.009441428 | AK289: 25614.55 | AO289: 45385 | AP289: 1256 | AQ289: 33025.82 | AR289: =AP289/AP290-1 -> 0.015647111 | AS289: =AQ289/AQ290-1 -> -0.00083229133
...

Sheet Cost of Debt
B4: Note : Sources' links are embedded in the text
C7: FY 2024-25 | D7: FY 2023-24 | E7: FY 2022-23 | F7: FY 2021-22 | G7: FY 2020-21
A8: In million Rs | B8: Interest Expense | C8: 385 | D8: 238 | E8: 251 | F8: 241 | G8: 222
B9: Short-term borrowings | C9: 2301 | D9: 1737 | E9: 2083 | F9: 1734 | G9: 1691
B10: Long-term borrowings | C10: 7523 | D10: 2938 | E10: 3708 | F10: 3441 | G10: 3497
B11: Total Borrowings | C11: =C9+C10 -> 9824 | D11: =D9+D10 -> 4675 | E11: =E9+E10 -> 5791 | F11: =F9+F10 -> 5175 | G11: =G9+G10 -> 5188
B12: Pre-tax Cost of Debt | C12: =C8/C11 -> 0.039189739 | D12: =D8/D11 -> 0.050909091 | E12: =E8/E11 -> 0.043343119 | F12: =F8/F11 -> 0.046570048 | G12: =G8/G11 -> 0.042791056
B13: Income Tax expense | C13: 9911 | D13: 4361 | E13: 11266 | F13: 13715 | G13: 12875
B14: Income Before Tax | C14: 44972 | D14: 25647 | E14: 49041 | F14: 62846 | G14: 55266
B15: Effective Tax Rate | C15: =C13/C14 -> 0.22038157 | D15: =D13/D14 -> 0.17003938 | E15: =E13/E14 -> 0.22972615 | F15: =F13/F14 -> 0.21823187 | G15: =G13/G14 -> 0.23296421
B16: Post-tax Cost of Debt (Kd) | C16: =C12*(1-C15) -> 0.030553043 | D16: =D12*(1-D15) -> 0.042252541 | E16: =E12*(1-E15) -> 0.033386071 | F16: =F12*(1-F15) -> 0.03640698 | G16: =G12*(1-G15) -> 0.032822272

Sheet PART A
H4: in millions | J4: FY 2024-25 | K4: FY 2023-24 | L4: FY 2022-23 | M4: FY 2021-22 | N4: FY 2020-21
I5: No. of outstanding shares | J5: 884,758,083 | K5: 882,522,894 | L5: 879,911,846 | M5: 873,959,406 | N5: 873,959,406
I6: Market Price (last trading day of FY) | J6: ='Cost of Equity'!AP45 -> 1418 | K6: ='Cost of Equity'!AJ45 -> 1250.4 | L6: ='Cost of Equity'!AD45 -> 1101.85 | M6: ='Cost of Equity'!X45 -> 1499.3 | N6: ='Cost of Equity'!R45 -> 991.25
I7: E | J7: =J5*J6/1000000 -> 1254587 | K7: =K5*K6/1000000 -> 1103506.6 | L7: =L5*L6/1000000 -> 969530.87 | M7: =M5*M6/1000000 -> 1310327.3 | N7: =N5*N6/1000000 -> 866312.26
I8: D | J8: ='Cost of Debt'!C11 -> 9824 | K8: ='Cost of Debt'!D11 -> 4675 | L8: ='Cost of Debt'!E11 -> 5791 | M8: ='Cost of Debt'!F11 -> 5175 | N8: ='Cost of Debt'!G11 -> 5188
I9: V (D+E) | J9: =J7+J8 -> 1264411 | K9: =K7+K8 -> 1108181.6 | L9: =L7+L8 -> 975321.87 | M9: =M7+M8 -> 1315502.3 | N9: =N7+N8 -> 871500.26
I10: Ke | J10: ='Cost of Equity'!B8 -> 0.056061821 | K10: ='Cost of Equity'!C8 -> 0.077139908 | L10: ='Cost of Equity'!D8 -> 0.066188259 | M10: ='Cost of Equity'!E8 -> 0.11947307 | N10: ='Cost of Equity'!F8 -> 0.065834202
I11: Kd | J11: ='Cost of Debt'!C16 -> 0.030553043 | K11: ='Cost of Debt'!D16 -> 0.042252541 | L11: ='Cost of Debt'!E16 -> 0.033386071 | M11: ='Cost of Debt'!F16 -> 0.03640698 | N11: ='Cost of Debt'!G16 -> 0.032822272
I12: WACC | J12: =(J11*J8/J9)+(J10*J7/J9) -> 0.055863627 | K12: =(K11*K8/K9)+(K10*K7/K9) -> 0.076992731 | L12: =(L11*L8/L9)+(L10*L7/L9) -> 0.065993495 | M12: =(M11*M8/M9)+(M10*M7/M9) -> 0.1191463 | N12: =(N11*N8/N9)+(N10*N7/N9) -> 0.065637684
H14: Cost of Equity Calculations - CAPM
H15: Cost of Debt Calculations - Total Interest expenses/Total Borrowings
B34: This Graph tells us how WACC is changing over years | H34: This graphs tells us how proportion of Ke, Kd and WACC is changing over years
G827: FY 2024-25 | H827: FY 2023-24 | I827: FY 2022-23 | J827: FY 2021-22 | K827: FY 2020-21
F828: Ke | G828: 0.034168651 | H828: 0.05770115 | I828: 0.046352436 | J828: 0.10281546 | K828: 0.051571276
F829: Kd | G829: 0.033923475 | H829: 0.01989725 | I829: 0.015431874 | J829: 0.04991063 | K829: 0.0455345
F830: WACC | G830: 0.034167953 | H830: 0.057701149 | I830: 0.045997264 | J830: 0.10226745 | K830: 0.051482873

Sheet Part B
I2: a) | J2: Theoretical ex-Rights price (TERP):
K3: (NP + S) / (N +1)
J6: Here, | K6: N = number of existing shares required for a rights share
K7: P = Cum-rights (Current) Market Price per share
K8: S = subscription price at which the rights shares are issued = Price x (1 - Discount rate for existing shareholders)
J10: From Question: | K10: N = | L10: 4
K11: P = Rs | L11: 1422 | M11: Value taken from Yahoo Finance for the closing price on 18/11/2025
K12: S = P x (1 - Discount) = P x (1- 0.1) = 0.9 x P | N12: =0.9 *L11 -> 1279.8
J14: So, | K14: TERP = Rs | L14: =(L10*L11 + N12) / (L10 +1) -> 1393.56
A17: Sources used : | B17: 1) All the formulas used have been taken directly from Uploaded Slides and Prasanna Chanda TB | J17: Value of One Right: | K17: (P - S) / ( N + 1)
B18: 2) The current market price was taken as the closing price on 18/11/2025 from Yahoo Finance
B19: The link to the page: https://finance.yahoo.com/quote/TECHM.NS/history/
J20: Value of One Right = Rs | K20: =(L11-N12)/(L10+1) -> 28.44
J23: Now,
J24: Percentage Price Drop: | K24: (P - TERP) / P
J26: Percentage Price Drop: | K26: =(L11-L14)/L11 -> 0.02
J29: In terms of % | K29: =100*K26 -> 2
I32: b) | J32: When a company conducts a rights issue, the share price tends to drop. This happens because the company issues new shares at a discounted subscription price, which ultimately lowers the weighted-average value per share. This process creates dilution; if you start with N existing shares, you end up with N+1 shares, leading to a decrease in the market value per share. Moreover, a portion of the original share’s value gets transferred into the tradeable right itself, aiming to offset the price decrease for shareholders. In essence, as outlined in the rights-issue framework, shareholder wealth stays unchanged only if the market price adjusts accurately to reflect the theoretical value post-rights issue.
I33: Answer

Sheet Part C
V2: Sensitivity Analysis
A3: Particulars | B3: Amount | F3: a) | G3: After-tax lease | H3: =$B$7*(1-$B$9) -> 3118473.7 | J3: b) | K3: Calculation of NPV of Lease | U3: c)
A4: Equipment Cost | B4: =25000000 -> 25000000 | G4: ="PVAF(" & TEXT(B10,"0.00%") & ",8)" -> PVAF(5.59%,8) | H4: =(1-(1+$B$10)^(-$B$5))/($B$10) -> 6.312742 | V4: WACC | W4: Useful Life | X4: PVAF | Y4: Depreciation | Z4: PV of Tax Shield | AA4: PV of Salvage | AB4: PV of Maintanence | AC4: PV of Ownership | AD4: PV of Lease
A5: Useful Life (n) | B5: =8 -> 8 | G5: PV of lease | H5: =$H$3*$H$4 -> 19686120 | K5: Year | L5: CFBTD | M5: Dep. | N5: CFADBT | O5: ="Tax saving at " & TEXT(B9,"0.00%") -> Tax saving at 22.04% | P5: CFAT | Q5: CFATBD | R5: ="Discount Rate at " & TEXT(B10,"0.00%") -> Discount Rate at 5.59% | S5: ="DCF at " & TEXT(B10,"0.00%") -> DCF at 5.59% | V5: =B10 -> 0.055863627 | W5: 8 | X5: =(1-(1+V5)^(-W5))/V5 -> 6.312742 | Y5: =($B$4-$B$6)/W5 -> 2812500 | Z5: =Y5*$B$9*X5 -> 3912783.7 | AA5: =$H$14/((1+V5)^(W5)) -> 1261709.8 | AB5: =$H$11*X5 -> 1476459 | AC5: =$B$4+AB5-Z5-AA5 -> 21301965 | AD5: =$H$3*X5 -> 19686120
A6: Salvage Value | B6: =2500000 -> 2500000 | K6: 0 | L6: 0 | R6: 1 | S6: =L6*R6 -> 0 | V6: Calculation of Sensitivity to Change in Cost of Capital
A7: Annual lease payment | B7: =4000000 -> 4000000 | G7: Depreciation | H7: =($B$4-$B$6)/$B$5 -> 2812500 | K7: 1 | L7: =-$B$7 -> -4000000 | M7: 0 | N7: =L7-M7 -> -4000000 | O7: =-N7*($B$9) -> 881526.28 | P7: =N7+O7 -> -3118473.7 | Q7: =P7+M7 -> -3118473.7 | R7: =(1)/(1+$B$10)^K7 -> 0.94709201 | S7: =Q7*R7 -> -2953481.5 | V7: =B10-0.01 -> 0.045863627 | W7: 8 | X7: =(1-(1+V7)^(-W7))/V7 -> 6.5726755 | Y7: =($B$4-$B$6)/W7 -> 2812500 | Z7: =Y7*$B$9*X7 -> 4073896.6 | AA7: =$H$14/((1+V7)^(W7)) -> 1361512.5 | AB7: =$H$11*X7 -> 1537253.7 | AC7: =$B$4+AB7-Z7-AA7 -> 21101845 | AD7: =$H$3*X7 -> 20496716
A8: Maintenance (if owned) | B8: =300000 -> 300000 | G8: Tax-shield on depreciation | H8: =$B$9*$H$7 -> 619823.17 | K8: 2 | L8: =-$B$7 -> -4000000 | M8: 0 | N8: =L8-M8 -> -4000000 | O8: =-N8*($B$9) -> 881526.28 | P8: =N8+O8 -> -3118473.7 | Q8: =P8+M8 -> -3118473.7 | R8: =(1)/(1+$B$10)^K8 -> 0.89698327 | S8: =Q8*R8 -> -2797218.7 | V8: =B10+0.01 -> 0.065863627 | W8: 8 | X8: =(1-(1+V8)^(-W8))/V8 -> 6.0682112 | Y8: =($B$4-$B$6)/W8 -> 2812500 | Z8: =Y8*$B$9*X8 -> 3761217.9 | AA8: =$H$14/((1+V8)^(W8)) -> 1170062.3 | AB8: =$H$11*X8 -> 1419266.8 | AC8: =$B$4+AB8-Z8-AA8 -> 21487987 | AD8: =$H$3*X8 -> 18923557
A9: Current Tax rate | B9: ='Cost of Debt'!C15 -> 0.22038157 | G9: PV of tax-shield | H9: =$H$4*$H$8 -> 3912783.7 | K9: 3 | L9: =-$B$7 -> -4000000 | M9: 0 | N9: =L9-M9 -> -4000000 | O9: =-N9*($B$9) -> 881526.28 | P9: =N9+O9 -> -3118473.7 | Q9: =P9+M9 -> -3118473.7 | R9: =(1)/(1+$B$10)^K9 -> 0.84952568 | S9: =Q9*R9 -> -2649223.5 | V9: Calculation of Sensitivity to Change in Useful Life
A10: Discount rate (WACC) | B10: ='PART A'!J12 -> 0.055863627 | K10: 4 | L10: =-$B$7 -> -4000000 | M10: 0 | N10: =L10-M10 -> -4000000 | O10: =-N10*($B$9) -> 881526.28 | P10: =N10+O10 -> -3118473.7 | Q10: =P10+M10 -> -3118473.7 | R10: =(1)/(1+$B$10)^K10 -> 0.80457898 | S10: =Q10*R10 -> -2509058.4 | V10: =B10 -> 0.055863627 | W10: 6 | X10: =(1-(1+V10)^(-W10))/V10 -> 4.9818841 | Y10: =($B$4-$B$6)/W10 -> 3750000 | Z10: =Y10*$B$9*X10 -> 4117182.9 | AA10: =$H$14/((1+V10)^(W10)) -> 1406614.6 | AB10: =$H$11*X10 -> 1165190.6 | AC10: =$B$4+AB10-Z10-AA10 -> 20641393 | AD10: =$H$3*X10 -> 15535875
G11: After-tax maintenance cost | H11: =$B$8*(1-$B$9) -> 233885.53 | K11: 5 | L11: =-$B$7 -> -4000000 | M11: 0 | N11: =L11-M11 -> -4000000 | O11: =-N11*($B$9) -> 881526.28 | P11: =N11+O11 -> -3118473.7 | Q11: =P11+M11 -> -3118473.7 | R11: =(1)/(1+$B$10)^K11 -> 0.76201032 | S11: =Q11*R11 -> -2376309.2 | V11: =B10 -> 0.055863627 | W11: 10 | X11: =(1-(1+V11)^(-W11))/V11 -> 7.5064992 | Y11: =($B$4-$B$6)/W11 -> 2250000 | Z11: =Y11*$B$9*X11 -> 3722161.7 | AA11: =$H$14/((1+V11)^(W11)) -> 1131732.6 | AB11: =$H$11*X11 -> 1755661.5 | AC11: =$B$4+AB11-Z11-AA11 -> 21901767 | AD11: =$H$3*X11 -> 23408820
G12: PV of maintenance | H12: =$H$4*$H$11 -> 1476459 | K12: 6 | L12: =-$B$7 -> -4000000 | M12: 0 | N12: =L12-M12 -> -4000000 | O12: =-N12*($B$9) -> 881526.28 | P12: =N12+O12 -> -3118473.7 | Q12: =P12+M12 -> -3118473.7 | R12: =(1)/(1+$B$10)^K12 -> 0.72169388 | S12: =Q12*R12 -> -2250583.4
K13: 7 | L13: =-$B$7 -> -4000000 | M13: 0 | N13: =L13-M13 -> -4000000 | O13: =-N13*($B$9) -> 881526.28 | P13: =N13+O13 -> -3118473.7 | Q13: =P13+M13 -> -3118473.7 | R13: =(1)/(1+$B$10)^K13 -> 0.68351051 | S13: =Q13*R13 -> -2131509.6
G14: After-tax salvage | H14: =$B$6*(1-$B$9) -> 1949046.1 | K14: 8 | L14: =-$B$7 -> -4000000 | M14: 0 | N14: =L14-M14 -> -4000000 | O14: =-N14*($B$9) -> 881526.28 | P14: =N14+O14 -> -3118473.7 | Q14: =P14+M14 -> -3118473.7 | R14: =(1)/(1+$B$10)^K14 -> 0.64734734 | S14: =Q14*R14 -> -2018735.7
G15: PV of salvage | H15: =$H$14/((1+$B$10)^$B$5) -> 1261709.8 | S15: =SUM(S6:S14) -> -19686120
G17: PV of Ownership | H17: =$B$4+$H$12-$H$9-$H$15 -> 21301965 | V17: WACC | W17: PV of Lease | X17: PV of Ownership | AB17: Useful Life | AC17: PV of Lease | AD17: PV of Ownership
G18: (Equipment cost+PV of maintainance - PV of Tax-shield - PV of Salvage) | K18: Calculation of NPV of Ownership | V18: =$V$7 -> 0.045863627 | W18: =$AD$7 -> 20496716 | X18: =$AC$7 -> 21101845 | AB18: 6 years | AC18: =$AD$10 -> 15535875 | AD18: =$AC$10 -> 20641393
N19: CFBTD + Dep | O19: CFADBT * Tax rate | P19: CFADBT + Tax saving | Q19: CFAT + Dep | V19: =V5 -> 0.055863627 | W19: =AD5 -> 19686120 | X19: =AC5 -> 21301965 | AB19: 8 years | AC19: =AD5 -> 19686120 | AD19: =AC5 -> 21301965
K20: Year | L20: CFBTD | M20: Dep. | N20: CFADBT | O20: ="Tax saving at " & TEXT(B9,"0.00%") -> Tax saving at 22.04% | P20: CFAT | Q20: CFATBD | R20: ="Discount Rate at " & TEXT(B10,"0.00%") -> Discount Rate at 5.59% | S20: ="DCF at " & TEXT(B10,"0.00%") -> DCF at 5.59% | V20: =$V$8 -> 0.065863627 | W20: =$AD$8 -> 18923557 | X20: =$AC$8 -> 21487987 | AB20: 10 years | AC20: =$AD$11 -> 23408820 | AD20: =$AC$11 -> 21901767
K21: 0 | L21: =-B4 -> -25000000 | R21: 1 | S21: =L21*R21 -> -25000000
G22: PV of Lease | H22: =$H$3*$H$4 -> 19686120 | K22: 1 | L22: =-$B$8 -> -300000 | M22: =($B$4-$B$6)/$B$5 -> 2812500 | N22: =L22-M22 -> -3112500 | O22: =-N22*($B$9) -> 685937.64 | P22: =N22+O22 -> -2426562.4 | Q22: =P22+M22 -> 385937.64 | R22: =(1)/(1+$B$10)^K22 -> 0.94709201 | S22: =Q22*R22 -> 365518.45
G23: PV of Ownership | H23: =$B$4+$H$12-$H$9-$H$15 -> 21301965 | K23: 2 | L23: =-$B$8 -> -300000 | M23: =($B$4-$B$6)/$B$5 -> 2812500 | N23: =L23-M23 -> -3112500 | O23: =-N23*($B$9) -> 685937.64 | P23: =N23+O23 -> -2426562.4 | Q23: =P23+M23 -> 385937.64 | R23: =(1)/(1+$B$10)^K23 -> 0.89698327 | S23: =Q23*R23 -> 346179.6
K24: 3 | L24: =-$B$8 -> -300000 | M24: =($B$4-$B$6)/$B$5 -> 2812500 | N24: =L24-M24 -> -3112500 | O24: =-N24*($B$9) -> 685937.64 | P24: =N24+O24 -> -2426562.4 | Q24: =P24+M24 -> 385937.64 | R24: =(1)/(1+$B$10)^K24 -> 0.84952568 | S24: =Q24*R24 -> 327863.94
K25: 4 | L25: =-$B$8 -> -300000 | M25: =($B$4-$B$6)/$B$5 -> 2812500 | N25: =L25-M25 -> -3112500 | O25: =-N25*($B$9) -> 685937.64 | P25: =N25+O25 -> -2426562.4 | Q25: =P25+M25 -> 385937.64 | R25: =(1)/(1+$B$10)^K25 -> 0.80457898 | S25: =Q25*R25 -> 310517.31
K26: 5 | L26: =-$B$8 -> -300000 | M26: =($B$4-$B$6)/$B$5 -> 2812500 | N26: =L26-M26 -> -3112500 | O26: =-N26*($B$9) -> 685937.64 | P26: =N26+O26 -> -2426562.4 | Q26: =P26+M26 -> 385937.64 | R26: =(1)/(1+$B$10)^K26 -> 0.76201032 | S26: =Q26*R26 -> 294088.46
K27: 6 | L27: =-$B$8 -> -300000 | M27: =($B$4-$B$6)/$B$5 -> 2812500 | N27: =L27-M27 -> -3112500 | O27: =-N27*($B$9) -> 685937.64 | P27: =N27+O27 -> -2426562.4 | Q27: =P27+M27 -> 385937.64 | R27: =(1)/(1+$B$10)^K27 -> 0.72169388 | S27: =Q27*R27 -> 278528.83
K28: 7 | L28: =-$B$8 -> -300000 | M28: =($B$4-$B$6)/$B$5 -> 2812500 | N28: =L28-M28 -> -3112500 | O28: =-N28*($B$9) -> 685937.64 | P28: =N28+O28 -> -2426562.4 | Q28: =P28+M28 -> 385937.64 | R28: =(1)/(1+$B$10)^K28 -> 0.68351051 | S28: =Q28*R28 -> 263792.43
K29: 8 | L29: =-$B$8+B6 -> 2200000 | M29: =($B$4-$B$6)/$B$5 -> 2812500 | N29: =L29-M29 -> -612500 | O29: =-N29*($B$9) -> 134983.71 | P29: =N29+O29 -> -477516.29 | Q29: =P29+M29 -> 2334983.7 | R29: =(1)/(1+$B$10)^K29 -> 0.64734734 | S29: =Q29*R29 -> 1511545.5
S30: =SUM(S21:S29) -> -21301965
K32: NPV of lease | L32: =S15 -> -19686120
K33: NPV of Ownership | L33: =S30 -> -21301965
K34: Since NPV of Leasing is greater we will choose to Lease the product
B36: `
K37: This table is used from the given excel of Capital Budgeting uploaded on Quantaaws
